Traceback (most recent call last):
  File "/home/runner/micromamba/envs/cookbook-dev/lib/python3.13/site-packages/jupyter_core/utils/__init__.py", line 154, in wrapped
    asyncio.get_running_loop()
    ~~~~~~~~~~~~~~~~~~~~~~~~^^
RuntimeError: no running event loop

During handling of the above exception, another exception occurred:

Traceback (most recent call last):
  File "/home/runner/micromamba/envs/cookbook-dev/lib/python3.13/site-packages/jupyter_cache/executors/utils.py", line 58, in single_nb_execution
    executenb(
    ~~~~~~~~~^
        nb,
        ^^^
    ...<4 lines>...
        **kwargs,
        ^^^^^^^^^
    )
    ^
  File "/home/runner/micromamba/envs/cookbook-dev/lib/python3.13/site-packages/nbclient/client.py", line 1319, in execute
    return NotebookClient(nb=nb, resources=resources, km=km, **kwargs).execute()
           ~~~~~~~~~~~~~~~~~~~~~~~~~~~~~~~~~~~~~~~~~~~~~~~~~~~~~~~~~~~~~~~~~~~^^
  File "/home/runner/micromamba/envs/cookbook-dev/lib/python3.13/site-packages/jupyter_core/utils/__init__.py", line 158, in wrapped
    return loop.run_until_complete(inner)
           ~~~~~~~~~~~~~~~~~~~~~~~^^^^^^^
  File "/home/runner/micromamba/envs/cookbook-dev/lib/python3.13/asyncio/base_events.py", line 725, in run_until_complete
    return future.result()
           ~~~~~~~~~~~~~^^
  File "/home/runner/micromamba/envs/cookbook-dev/lib/python3.13/site-packages/nbclient/client.py", line 709, in async_execute
    await self.async_execute_cell(
        cell, index, execution_count=self.code_cells_executed + 1
    )
  File "/home/runner/micromamba/envs/cookbook-dev/lib/python3.13/site-packages/nbclient/client.py", line 1062, in async_execute_cell
    await self._check_raise_for_error(cell, cell_index, exec_reply)
  File "/home/runner/micromamba/envs/cookbook-dev/lib/python3.13/site-packages/nbclient/client.py", line 918, in _check_raise_for_error
    raise CellExecutionError.from_cell_and_msg(cell, exec_reply_content)
nbclient.exceptions.CellExecutionError: An error occurred while executing the following cell:
------------------
basin_mask = merged_mask(basins, ds[['lat', 'lon']])
------------------


[31m---------------------------------------------------------------------------[39m
[31mTypeError[39m                                 Traceback (most recent call last)
[36mCell[39m[36m [39m[32mIn[11][39m[32m, line 1[39m
[32m----> [39m[32m1[39m basin_mask = [43mmerged_mask[49m[43m([49m[43mbasins[49m[43m,[49m[43m [49m[43mds[49m[43m[[49m[43m[[49m[33;43m'[39;49m[33;43mlat[39;49m[33;43m'[39;49m[43m,[49m[43m [49m[33;43m'[39;49m[33;43mlon[39;49m[33;43m'[39;49m[43m][49m[43m][49m[43m)[49m

[36mFile [39m[32m~/micromamba/envs/cookbook-dev/lib/python3.13/site-packages/xmip/regionmask.py:188[39m, in [36mmerged_mask[39m[34m(basins, ds, lon_name, lat_name, merge_dict, verbose)[39m
[32m    137[39m [38;5;28;01mdef[39;00m[38;5;250m [39m[34mmerged_mask[39m(
[32m    138[39m     basins, ds, lon_name=[33m"[39m[33mlon[39m[33m"[39m, lat_name=[33m"[39m[33mlat[39m[33m"[39m, merge_dict=[38;5;28;01mNone[39;00m, verbose=[38;5;28;01mFalse[39;00m
[32m    139[39m ):
[32m    140[39m [38;5;250m    [39m[33;03m"""Combine geographical basins (from regionmask) to larger ocean basins.[39;00m
[32m    141[39m 
[32m    142[39m [33;03m    Parameters[39;00m
[32m   (...)[39m[32m    186[39m 
[32m    187[39m [33;03m    """[39;00m
[32m--> [39m[32m188[39m     mask = [43mbasins[49m[43m.[49m[43mmask[49m[43m([49m[43mds[49m[43m,[49m[43m [49m[43mlon_name[49m[43m=[49m[43mlon_name[49m[43m,[49m[43m [49m[43mlat_name[49m[43m=[49m[43mlat_name[49m[43m)[49m
[32m    190[39m     [38;5;28;01mif[39;00m merge_dict [38;5;129;01mis[39;00m [38;5;28;01mNone[39;00m:
[32m    191[39m         merge_dict = _default_merge_dict()

[31mTypeError[39m: Regions.mask() got an unexpected keyword argument 'lon_name'

